Workbook

Sheet Overview of workbook
A2: Animal Product Impacts - Calculations Workbook
A4: This workbook estimates the relationship between the amounts of various animal food products consumed and the impact on animal lives.
A6: Worksheet descriptions
A8: Summary - Lives per pound - summarises the key outputs of the analysis: how many animal lives go into each pound of animal product. Two estimates are given, for direct and total (direct + indirect) lives per pound.
A10: Overall estimates - carries out the overall calculations of the main outputs in the analysis (summarised in the summary sheet) using the data and estimates from the other sheets in the workbook.
A12: Milk solids proportion – identifies amount of milk solids of various dairy products relative to dairy milk for purposes of allocating relative degree impacts.
A14: Fish and shellfish calculations – includes estimated weights of fish and shellfish, and the additional lives cost due to feed fish and bycatch using data from 'Feed fish and bycatch calculations' sheet, and additional lives due to mortality. Also includes Welfare Footprint Data including finfish lifespan and mortality estimates from welfarefootprint.org
A16: Feed fish - estimates the average number of feed fish per farmed finfish, shellfish, pig, broiler chicken and layer hen.
A18: Mortality - estimates the mortality rates and additional lives per animal due to mortality for livestock.
A20: FAO livestock data - contains data from FAO on the primary weights of livestock in the U.S.
A22: USDA food loss data - contains data from USDA on the proportion of food lost from primary to consumption stage.
A24: Elasticity adjustments – for potential future use to estimate effects with attention to elasticity of demand. Would need more research and differentiation among aquatic animals, etc. than is available here at this stage
A26: Days of their lives – focus on number of animals days in confinement. Not ready for use.

Sheet Summary - Lives per pound
A1: Lives per pound estimates
A2: Animal Product Type | B2: Direct lives per pound purchased for retail sale | C2: Total lives per pound purchased for retail sale (direct + indirect) | E2: Direct lives per kilogram for retail sale | F2: Total lives per kilogram purchased for retail sale (direct + indirect)
A3: Animal fats | B3: ='Overall Estimates'!C18 -> 0.10617053 | C3: ='Overall Estimates'!D18 -> 0.67132313 | E3: =2.20462*B3 -> 0.23406568 | F3: =2.20462*C3 -> 1.4800124
A4: Beef | B4: ='Overall Estimates'!C19 -> 0.001724731 | C4: ='Overall Estimates'!D19 -> 0.0019218627 | E4: =2.20462*B4 -> 0.0038023765 | F4: =2.20462*C4 -> 0.004236977
A5: Chicken | B5: ='Overall Estimates'!C20 -> 0.29258396 | C5: ='Overall Estimates'!D20 -> 0.33032716 | E5: =2.20462*B5 -> 0.64503644 | F5: =2.20462*C5 -> 0.72824585
A6: Eggs | B6: ='Overall Estimates'!C21 -> 0.016853824 | C6: ='Overall Estimates'!D21 -> 0.042759475 | E6: =2.20462*B6 -> 0.037156278 | F6: =2.20462*C6 -> 0.094268393
A7: Goat | B7: ='Overall Estimates'!C22 -> 0.065031241 | C7: ='Overall Estimates'!D22 -> 0.089450025 | E7: =2.20462*B7 -> 0.14336918 | F7: =2.20462*C7 -> 0.19720331
A8: Lamb/mutton | B8: ='Overall Estimates'!C23 -> 0.036128467 | C8: ='Overall Estimates'!D23 -> 0.044050511 | E8: =2.20462*B8 -> 0.079649542 | F8: =2.20462*C8 -> 0.097114639
A9: Pork | B9: ='Overall Estimates'!C24 -> 0.0071941778 | C9: ='Overall Estimates'!D24 -> 0.27300432 | E9: =2.20462*B9 -> 0.015860428 | F9: =2.20462*C9 -> 0.60187079
A10: Turkey | B10: ='Overall Estimates'!C25 -> 0.053487207 | C10: ='Overall Estimates'!D25 -> 0.058296683 | E10: =2.20462*B10 -> 0.11791897 | F10: =2.20462*C10 -> 0.12852203
A11: Unidentified meat | B11: ='Overall Estimates'!C26 -> 0.14293917 | C11: ='Overall Estimates'!D26 -> 0.22232666 | E11: =2.20462*B11 -> 0.31512655 | F11: =2.20462*C11 -> 0.49014579
A12: Dairy milk | B12: ='Overall Estimates'!C27 -> 1.2828204e-05 | C12: ='Overall Estimates'!D27 -> 1.3970792e-05 | E12: =2.20462*B12 -> 2.8281316e-05 | F12: =2.20462*C12 -> 3.0800287e-05
A13: Butter | B13: ='Overall Estimates'!C28 -> 8.0689406e-05 | C13: ='Overall Estimates'!D28 -> 8.7876279e-05 | E13: =2.20462*B13 -> 0.00017788948 | F13: =2.20462*C13 -> 0.0001937338
A14: Buttermilk | B14: ='Overall Estimates'!C29 -> 1.3136081e-05 | C14: ='Overall Estimates'!D29 -> 1.4306091e-05 | E14: =2.20462*B14 -> 2.8960068e-05 | F14: =2.20462*C14 -> 3.1539493e-05
... A73: bluefin tuna | B73: ='Overall Estimates'!C88 -> 0.00548367 | C73: ='Overall Estimates'!D88 -> 0.0059223636 | E73: =2.20462*B73 -> 0.012089409 | F73: =2.20462*C73 -> 0.013056561

Sheet Milk solids proportion
A1: Milk Solids relative to milk
A2: Feitz, A.J., Lundie, S., Dennien, G. et al. Generation of an Industry-specific Physico-chemical Allocation Matrix. Application in the Dairy Industry and Implications for Systems Analysis (9 pp). Int J Life Cycle Assessment 12, 109–117 (2007).
B3: Milk solids ratio | C3: kgs per life relative to milk | D3: Feitz et al
A4: dairy milk | B4: 1 | C4: =1/B4 -> 1 | D4: Table 2
A5: butter | B5: 6.29 | C5: =1/B5 -> 0.15898251 | D5: Table 2
A6: buttermilk | B6: 1.024 | C6: =1/B6 -> 0.9765625 | D6: Table 1
A7: cheese | B7: 4.57 | C7: =1/B7 -> 0.21881838 | D7: Table 2
A8: concentrated milk | B8: 3 | C8: =1/B8 -> 0.33333333 | D8: Various
A9: cream | B9: 3.36 | C9: =1/B9 -> 0.29761905 | D9: Table 2
A10: ghee | B10: 7.5 | C10: =1/B10 -> 0.13333333 | D10: Table 2
A11: ice cream | B11: 1.64 | C11: =1/B11 -> 0.6097561 | D11: Table 2
A12: lactose powder | B12: 7.14 | C12: =1/B12 -> 0.14005602 | D12: Table 2
A13: low fat yogurt | B13: 1.112 | C13: =1/B13 -> 0.89928058 | D13: Table 1
A14: milk powder | B14: 7.14 | C14: =1/B14 -> 0.14005602 | D14: Table 2
A15: skim milk | B15: 0.744 | C15: =1/B15 -> 1.344086 | D15: Table 1
... A17: yogurt | B17: 1.136 | C17: =1/B17 -> 0.88028169 | D17: Table 1

Sheet Overall Estimates
A1: Overall estimates: Lives per kilogram and per pound of product
A3: Livestock estimates (for fish and shellfish estimates, see fish and shellfish worksheet)
B4: Beef | C4: Lamb/Mutton | D4: Pork | E4: Goat | F4: Chicken | G4: Turkey | H4: Eggs | I4: Dairy milk | J4: Ice cream | K4: Cheese | L4: Yogurt | M4: Butter | N4: Buttermilk | O4: Concentrated milk | P4: Cream | Q4: Ghee | R4: Lactose Powder | S4: Low fat yogurt | T4: Milk powder | U4: Skim Milk | V4: Whey powder
A5: Yield/Carcass Weight per animal, FAO, 2025, (kilograms) | B5: ='FAO livestock data U.S.'!G7 -> 369 | C5: ='FAO livestock data U.S.'!G14 -> 27 | D5: ='FAO livestock data U.S.'!G9 -> 97 | E5: ='FAO livestock data U.S.'!G15 -> 15 | F5: ='FAO livestock data U.S.'!G8 -> 2.095 | G5: ='FAO livestock data U.S.'!G10 -> 11.46 | H5: ='FAO livestock data U.S.'!G6 -> 17.077 | I5: ='FAO livestock data U.S.'!G12 -> 10926.002 | J5: ='FAO livestock data U.S.'!G12 -> 10926.002 | K5: ='FAO livestock data U.S.'!G12 -> 10926.002 | L5: ='FAO livestock data U.S.'!G12 -> 10926.002 | M5: ='FAO livestock data U.S.'!G12 -> 10926.002 | N5: ='FAO livestock data U.S.'!G12 -> 10926.002 | O5: ='FAO livestock data U.S.'!G12 -> 10926.002 | P5: ='FAO livestock data U.S.'!G12 -> 10926.002 | Q5: ='FAO livestock data U.S.'!G12 -> 10926.002 | R5: ='FAO livestock data U.S.'!G12 -> 10926.002 | S5: ='FAO livestock data U.S.'!G12 -> 10926.002 | T5: ='FAO livestock data U.S.'!G12 -> 10926.002 | U5: ='FAO livestock data U.S.'!G12 -> 10926.002 | V5: ='FAO livestock data U.S.'!G12 -> 10926.002
A6: Years producing product (eggs and dairy) | B6: 1 | C6: 1 | D6: 1 | E6: 1 | F6: 1 | G6: 1 | H6: 1.6 | I6: 3 | J6: 3 | K6: 3 | L6: 3 | M6: 3 | N6: 3 | O6: 3 | P6: 3 | Q6: 3 | R6: 3 | S6: 3 | T6: 3 | U6: 3 | V6: 3
A7: Loss adjusted proportion (primary to retail weight) | B7: ='Percent retail from FAO yield'!F2 -> 0.65 | C7: ='Percent retail from FAO yield'!F6 -> 0.465 | D7: ='Percent retail from FAO yield'!F3 -> 0.65 | E7: ='Percent retail from FAO yield'!F7 -> 0.465 | F7: ='Percent retail from FAO yield'!F4 -> 0.74 | G7: ='Percent retail from FAO yield'!F5 -> 0.74 | H7: ='Percent retail from FAO yield'!G8 -> 0.985 | I7: ='Percent retail from FAO yield'!G9 -> 0.94929354 | J7: ='Percent retail from FAO yield'!G9 -> 0.94929354 | K7: ='Percent retail from FAO yield'!G9 -> 0.94929354 | L7: ='Percent retail from FAO yield'!G9 -> 0.94929354 | M7: ='Percent retail from FAO yield'!G9 -> 0.94929354 | N7: ='Percent retail from FAO yield'!G9 -> 0.94929354 | O7: ='Percent retail from FAO yield'!G9 -> 0.94929354 | P7: ='Percent retail from FAO yield'!G9 -> 0.94929354 | Q7: ='Percent retail from FAO yield'!G9 -> 0.94929354 | R7: ='Percent retail from FAO yield'!G9 -> 0.94929354 | S7: ='Percent retail from FAO yield'!G9 -> 0.94929354 | T7: ='Percent retail from FAO yield'!G9 -> 0.94929354 | U7: ='Percent retail from FAO yield'!G9 -> 0.94929354 | V7: ='Percent retail from FAO yield'!G9 -> 0.94929354
A8: Milk solids adjustment relative to milk | I8: 1 | J8: ='Milk solids proportion'!C11 -> 0.6097561 | K8: ='Milk solids proportion'!C7 -> 0.21881838 | L8: ='Milk solids proportion'!C17 -> 0.88028169 | M8: ='Milk solids proportion'!C5 -> 0.15898251 | N8: ='Milk solids proportion'!C6 -> 0.9765625 | O8: ='Milk solids proportion'!C8 -> 0.33333333 | P8: ='Milk solids proportion'!C9 -> 0.29761905 | Q8: ='Milk solids proportion'!C10 -> 0.13333333 | R8: ='Milk solids proportion'!C12 -> 0.14005602 | S8: ='Milk solids proportion'!C13 -> 0.89928058 | T8: ='Milk solids proportion'!C14 -> 0.14005602 | U8: ='Milk solids proportion'!C15 -> 1.344086 | V8: ='Milk solids proportion'!C16 -> 0.13869626
A9: Total retail weight per life (kilograms) | B9: =B5*B6*B7 -> 239.85 | C9: =C5*C6*C7 -> 12.555 | D9: =D5*D6*D7 -> 63.05 | E9: =E5*E6*E7 -> 6.975 | F9: =F5*F6*F7 -> 1.5503 | G9: =G5*G6*G7 -> 8.4804 | H9: =H5*H6*H7 -> 26.913352 | I9: =I5*I6*I7 -> 31115.95 | J9: =J5*J6*J7*J8 -> 18973.14 | K9: =K5*K6*K7*K8 -> 6808.7417 | L9: =L5*L6*L7*L8 -> 27390.801 | M9: =M5*M6*M7*M8 -> 4946.8918 | N9: =N5*N6*N7*N8 -> 30386.669 | O9: =O5*O6*O7*O8 -> 10371.983 | P9: =P5*P6*P7*P8 -> 9260.6993 | Q9: =Q5*Q6*Q7*Q8 -> 4148.7933 | ... V9: =V5*V6*V7*V8 -> 4315.6657
A10: Total retail weight per life including indirect effects (kilograms) | B10: =(B5*B6*B7)/(1+Mortality!C4) -> 215.24781 | C10: =(C5*C6*C7)/(1+Mortality!C10) -> 10.297109 | D10: =(D5*D6*D7)/(1+(1.123*'Feed fish'!B12)+Mortality!C7) -> 1.6614862 | E10: =(E5*E6*E7)/(1+Mortality!C11) -> 5.0709087 | F10: =(F5*F6*F7)/(1+'Feed fish'!B27+Mortality!C5) -> 1.3731626 | G10: =(G5*G6*G7)/(1+Mortality!C9) -> 7.780767 | H10: =(H5*H6*H7)/(1+'Feed fish'!B28+Mortality!C8) -> 10.608009 | I10: =(I5*I6*I7)/(1+Mortality!C6) -> 28571.163 | J10: =(J5*J6*J7*J8)/(1+Mortality!C6) -> 17421.441 | K10: =(K5*K6*K7*K8)/(1+Mortality!C6) -> 6251.8956 | L10: =(L5*L6*L7*L8)/(1+Mortality!C6) -> 25150.671 | M10: =(M5*M6*M7*M8)/(1+Mortality!C6) -> 4542.3152 | N10: =(N5*N6*N7*N8)/(1+Mortality!C6) -> 27901.526 | O10: =(O5*O6*O7*O8)/(1+Mortality!C6) -> 9523.7209 | P10: =(P5*P6*P7*P8)/(1+Mortality!C6) -> 8503.3222 | Q10: =(Q5*Q6*Q7*Q8)/(1+Mortality!C6) -> 3809.4884 | R10: =(R5*R6*R7*R8)/(1+Mortality!C6) -> 4001.5634 | S10: =(S5*S6*S7*S8)/(1+Mortality!C6) -> 25693.492 | T10: =(T5*T6*T7*T8)/(1+Mortality!C6) -> 4001.5634 | U10: =(U5*U6*U7*U8)/(1+Mortality!C6) -> 38402.1 | V10: =(V5*V6*V7*V8)/(1+Mortality!C6) -> 3962.7133
A11: Beef/Dairy lives allocation adjustment | B11: 0.912 | I11: 0.88 | J11: 0.88 | K11: 0.88 | L11: 0.88 | M11: 0.88 | N11: 0.88 | O11: 0.88 | P11: 0.88 | Q11: 0.88 | R11: 0.88 | S11: 0.88 | T11: 0.88 | U11: 0.88 | V11: 0.88
A12: lives per kilogram of consumable product | B12: =B11*(1/B9) -> 0.0038023765 | C12: =(1/C9) -> 0.079649542 | D12: =(1/D9) -> 0.015860428 | E12: =(1/E9) -> 0.14336918 | F12: =(1/F9) -> 0.64503644 | G12: =(1/G9) -> 0.11791897 | H12: =(1/H9) -> 0.037156278 | I12: =I11*((1/I9)) -> 2.8281316e-05 | J12: =J11*((1/J9)) -> 4.6381358e-05 | K12: =K11*((1/K9)) -> 0.00012924561 | L12: =L11*(1/L9) -> 3.2127575e-05 | M12: =M11*(1/M9) -> 0.00017788948 | N12: =N11*(1/N9) -> 2.8960068e-05 | O12: =O11*(1/O9) -> 8.4843948e-05 | P12: =P11*(1/P9) -> 9.5025222e-05 | Q12: =Q11*(1/Q9) -> 0.00021210987 | R12: =R11*(1/R9) -> 0.0002019286 | S12: =S11*(1/S9) -> 3.1448823e-05 | ... V12: =V11*(1/V9) -> 0.00020390829
A13: lives per kilogram of consumable product including indirect effects | B13: =B11*(1/B10) -> 0.004236977 | C13: =(1/C10) -> 0.097114639 | D13: =(1/D10) -> 0.60187079 | E13: =(1/E10) -> 0.19720331 | F13: =(1/F10) -> 0.72824585 | G13: =(1/G10) -> 0.12852203 | H13: =(1/H10) -> 0.094268393 | I13: =I11*(1/I10) -> 3.0800287e-05 | J13: =J11*(1/J10) -> 5.051247e-05 | K13: =K11*(1/K10) -> 0.00014075731 | L13: =L11*(1/L10) -> 3.4989126e-05 | M13: =M11*(1/M10) -> 0.0001937338 | N13: =N11*(1/N10) -> 3.1539493e-05 | O13: =O11*(1/O10) -> 9.240086e-05 | P13: =P11*(1/P10) -> 0.00010348896 | ... V13: =V11*(1/V10) -> 0.00022207007
B17: Animal Product Type | C17: Direct lives per pound consumed | D17: Total lives per pound consumed (direct + indirect) | E17: Milk solids proportion
B18: Animal fats | C18: =((0.37*C24)+(0.32*C19)+(0.2*C20)+(0.06*C23)+(0.05*C53)) -> 0.10617053 | D18: =((0.37*D24)+(0.32*D19)+(0.2*D20)+(0.06*D23)+(0.05*D53)) -> 0.67132313
B19: Beef | C19: =B12/2.20462 -> 0.001724731 | D19: =B13/2.20462 -> 0.0019218627
B20: Chicken | C20: =F12/2.20462 -> 0.29258396 | D20: =F13/2.20462 -> 0.33032716
B21: Eggs | C21: =H12/2.20462 -> 0.016853824 | D21: =H13/2.20462 -> 0.042759475
B22: Goat | C22: =E12/2.20462 -> 0.065031241 | D22: =E13/2.20462 -> 0.089450025
B23: Lamb/mutton | C23: =C12/2.20462 -> 0.036128467 | D23: =C13/2.20462 -> 0.044050511
B24: Pork | C24: =D12/2.20462 -> 0.0071941778 | D24: =D13/2.20462 -> 0.27300432
B25: Turkey | C25: =G12/2.20462 -> 0.053487207 | D25: =G13/2.20462 -> 0.058296683
B26: Unidentified meat | C26: =(0.48*C20)+(0.28*C19)+(0.23*C24)+(0.01*C23) -> 0.14293917 | D26: =(0.48*D20)+(0.28*D19)+(0.23*D24)+(0.01*D23) -> 0.22232666
B27: Dairy milk | C27: =(I12/2.20462) -> 1.2828204e-05 | D27: =I13/2.20462 -> 1.3970792e-05 | E27: ='Milk solids proportion'!B4 -> 1
B28: Butter | C28: =M12/2.20462 -> 8.0689406e-05 | D28: =M13/2.20462 -> 8.7876279e-05 | E28: ='Milk solids proportion'!B5 -> 6.29
B29: Buttermilk | C29: =N12/2.20462 -> 1.3136081e-05 | D29: =N13/2.20462 -> 1.4306091e-05 | E29: ='Milk solids proportion'!B6 -> 1.024
B30: Cheese | C30: =K12/2.20462 -> 5.8624894e-05 | D30: =K13/2.20462 -> 6.3846518e-05 | E30: ='Milk solids proportion'!B7 -> 4.57
B31: Concentrated milk | C31: =O12/2.20462 -> 3.8484613e-05 | D31: =O13/2.20462 -> 4.1912375e-05 | E31: ='Milk solids proportion'!B8 -> 3
B32: Cream | C32: =P12/2.20462 -> 4.3102767e-05 | D32: =P13/2.20462 -> 4.694186e-05 | E32: ='Milk solids proportion'!B9 -> 3.36
B33: Ghee | C33: =Q12/2.20462 -> 9.6211533e-05 | D33: =Q13/2.20462 -> 0.00010478094 | E33: ='Milk solids proportion'!B10 -> 7.5
B34: Ice cream | C34: =J12/2.20462 -> 2.1038255e-05 | D34: =J13/2.20462 -> 2.2912098e-05 | E34: ='Milk solids proportion'!B11 -> 1.64
B35: Lactose powder | C35: =R12/2.20462 -> 9.1593379e-05 | D35: =R13/2.20462 -> 9.9751452e-05 | E35: ='Milk solids proportion'!B12 -> 7.14
B36: Low fat yogurt | C36: =S12/2.20462 -> 1.4264963e-05 | D36: =S13/2.20462 -> 1.553552e-05 | E36: ='Milk solids proportion'!B13 -> 1.112
B37: Milk powder | C37: =T12/2.20462 -> 9.1593379e-05 | D37: =T13/2.20462 -> 9.9751452e-05 | E37: ='Milk solids proportion'!B14 -> 7.14
B38: Skim milk | C38: =U12/2.20462 -> 9.5441841e-06 | D38: =U13/2.20462 -> 1.0394269e-05 | E38: ='Milk solids proportion'!B15 -> 0.744
B39: Whey powder | C39: =V12/2.20462 -> 9.2491354e-05 | D39: =V13/2.20462 -> 0.00010072941 | E39: ='Milk solids proportion'!B16 -> 7.21
B40: Yogurt | C40: =L12/2.20462 -> 1.457284e-05 | D40: =L13/2.20462 -> 1.5870819e-05 | E40: ='Milk solids proportion'!B17 -> 1.136
B41: anchovies | C41: ='Fish and shellfish calculation'!J2 -> 36.618162 | D41: ='Fish and shellfish calculation'!M2 -> 39.547615
B42: bass | C42: ='Fish and shellfish calculation'!J3 -> 0.18122315 | D42: ='Fish and shellfish calculation'!M3 -> 2.0493389
B43: bass (wild caught) | C43: ='Fish and shellfish calculation'!J4 -> 0.15386051 | D43: ='Fish and shellfish calculation'!M4 -> 0.16616935
B44: bass (farmed) | C44: ='Fish and shellfish calculation'!J5 -> 1.6356312 | D44: ='Fish and shellfish calculation'!M5 -> 13.897033
...

Sheet Fish and shellfish calculation
A1: DIRECT AND TOTAL LIVES CALCULATION PROCESS | B1: Live weight kg | C1: From Gephart et al: Edible Percentage (%) | D1: From IFFO.com FIFO | E1: Assuming 26.6054 fish per kg of FMFO (see E108) & adjusted by column I | F1: Fed fish * 1.123 for slippage and bycatch mortality accompanying catch of fish for fish feed. | G1: Fish used per kg edible of purchased fish from aquaculture F/(B*C) | H1: Fed fish per lb edible G*.453692 | I1: Portion of US consumption from aquaculture | J1: Lives per lb direct 1/(B*C*2.20462) | K1: mortality | L1: additional lives per lb direct due to mortality | M1: Lives per lb total Farmed fish: =(H+I+K) Wild fish: =J*1.08 for bycatch Trapped cephalopods, lobster, crab: =J*2 for bait + bycatch
A2: anchovies | B2: =H152 -> 0.02058 | C2: 0.6019 | J2: =(1/(B2*C2*2.20462)) -> 36.618162 | M2: =1.08*J2 -> 39.547615
A3: bass | B3: =H153 -> 5.2961327 | C3: 0.4726 | D3: =((0.75*0.26)+(0.25*0.75)) -> 0.3825 | E3: =(B3*D3*$E$108)*I3 -> 9.0006915 | F3: =E3*1.123 -> 10.107777 | G3: =F3/(B3*C3) -> 4.0383417 | H3: =G3*0.453692 -> 1.8321633 | I3: 0.167 | J3: =(1/(B3*C3*2.20462)) -> 0.18122315 | K3: =$G$71 -> 0.441 | L3: =J3*(K3/(1-K3))*I3 -> 0.023875745 | M3: =(H3+J3+L3)+(0.08*(1-I3)*J3) -> 2.0493389
A4: bass (wild-caught) | B4: =H154 -> 6.238 | C4: 0.4726 | J4: =(1/(B4*C4*2.20462)) -> 0.15386051 | M4: =(H4+J4+L4)+(0.08*(1-I4)*J4) -> 0.16616935
A5: bass (farmed) | B5: =H155 -> 0.586796 | C5: 0.4726 | D5: =((0.75*0.26)+(0.25*0.75)) -> 0.3825 | E5: =(B5*D5*$E$108)*I5 -> 5.9715586 | F5: =E5*1.123 -> 6.7060603 | G5: =F5/(B5*C5) -> 24.181687 | H5: =G5*0.453692 -> 10.971038 | I5: 1 | J5: =(1/(B5*C5*2.20462)) -> 1.6356312 | K5: =$G$71 -> 0.441 | L5: =J5*(K5/(1-K5))*I5 -> 1.2903638 | M5: =(H5+J5+L5)+(0.08*(1-I5)*J5) -> 13.897033
A6: carp | B6: =H156 -> 12.601 | C6: 0.54 | J6: =(1/(B6*C6*2.20462)) -> 0.066660334 | M6: =H6+J6+L6 -> 0.066660334
A7: carp silver or bighead carp | B7: =H158 -> 2.6421979 | C7: 0.54 | J7: =(1/(B7*C7*2.20462)) -> 0.31791216 | M7: =H7+J7+L7 -> 0.31791216
A8: catfish | B8: =H158 -> 2.6421979 | C8: 0.5305 | D8: 0.26 | E8: =(B8*D8*$E$108)*I8 -> 16.942892 | F8: =E8*1.123 -> 19.026868 | G8: =F8/(B8*C8) -> 13.574272 | H8: =G8*0.453692 -> 6.1585388 | I8: 0.927 | J8: =(1/(B8*C8*2.20462)) -> 0.32360522 | K8: =$G$64 -> 0.48541667 | L8: =J8*(K8/(1-K8))*I8 -> 0.28297901 | M8: =(H8+J8+L8)+(0.08*(1-I8)*J8) -> 6.7670129
A9: catfish (wild-caught) | B9: =H159 -> 25.366448 | C9: 0.5305 | J9: =(1/(B9*C9*2.20462)) -> 0.033707086 | M9: =1.08*J9 -> 0.036403653
A10: catfish (farmed) | B10: =H160 -> 0.843876 | C10: 0.5305 | D10: 0.26 | E10: =(B10*D10*$E$108)*I10 -> 5.8374221 | F10: =E10*1.123 -> 6.555425 | G10: =F10/(B10*C10) -> 14.643228 | H10: =G10*0.453692 -> 6.6435154 | I10: 1 | J10: =(1/(B10*C10*2.20462)) -> 1.0132165 | K10: =$G$64 -> 0.48541667 | L10: =J10*(K10/(1-K10))*I10 -> 0.95578718 | M10: =(H10+J10+L10)+(0.08*(1-I10)*J10) -> 8.6125191
A11: cod | B11: =H161 -> 2.696 | C11: 0.4962 | J11: =(1/(B11*C11*2.20462)) -> 0.33907019 | M11: =1.08*J11 -> 0.3661958
A12: congers | B12: =H162 -> 10.595343 | C12: 0.4726 | J12: =(1/(B12*C12*2.20462)) -> 0.090585257 | M12: =1.08*J12 -> 0.097832077
A13: crab | B13: =H163 -> 1.2033874 | C13: 0.391 | J13: =(1/(B13*C13*2.20462)) -> 0.96401553 | M13: =2*J13 -> 1.9280311 | N13: +1 life per life for trap bait plus bycatch
A14: fish (finfish) | B14: =B88 -> 0.96168613 | C14: =B89 -> 0.55779221 | J14: =$D$92 -> 0.84544549 | M14: =$D$93 -> 10.019761 | N14: fish (finfish) cfp/faunalytics
A15: flounder | B15: =H165 -> 0.463221 | C15: 0.5275 | J15: =(1/(B15*C15*2.20462)) -> 1.8563316 | M15: =1.08*J15 -> 2.0048381
A16: haddock | B16: =H166 -> 1.35 | C16: 0.4962 | J16: =(1/(B16*C16*2.20462)) -> 0.67713573 | M16: =1.08*J16 -> 0.73130659
A17: hake | B17: =H167 -> 1.005285 | C17: 0.4962 | J17: =(1/(B17*C17*2.20462)) -> 0.90932744 | M17: =1.08*J17 -> 0.98207363
A18: halibut | B18: =H168 -> 11.43318 | C18: 0.5275 | J18: =(1/(B18*C18*2.20462)) -> 0.075210201 | M18: =1.08*J18 -> 0.081227018
A19: herring | B19: =H169 -> 0.249212 | C19: 0.6019 | J19: =(1/(B19*C19*2.20462)) -> 3.0239386 | M19: =1.08*J19 -> 3.2658536
A20: jacks | B20: =H170 -> 1.499787 | C20: 0.5409 | J20: =(1/(B20*C20*2.20462)) -> 0.55913888 | M20: =1.08*J20 -> 0.60386999
A21: lobster | B21: =H171 -> 0.57 | C21: 0.2 | J21: =(1/(B21*C21*2.20462)) -> 3.9788852 | M21: =2*J21 -> 7.9577703 | N21: +1 life per life for trap bait plus bycatch
A22: mahi-mahi | B22: 10 | C22: 0.6174 | J22: =(1/(B22*C22*2.20462)) -> 0.073468239 | M22: =1.08*J22 -> 0.079345698
A23: milkfish | B23: =H173 -> 0.38625 | C23: 0.61 | D23: 0.75 | E23: =(B23*D23*$E$108)*I23 -> 7.3218777 | F23: =E23*1.123 -> 8.2224687 | G23: =F23/(B23*C23) -> 34.89827 | H23: =G23*0.453692 -> 15.833066 | I23: 0.95 | J23: =(1/(B23*C23*2.20462)) -> 1.9251649 | K23: =$G$83 -> 0.4725 | L23: =J23*(K23/(1-K23))*I23 -> 1.6382149 | M23: =(H23+J23+L23)+(0.08*(1-I23)*J23) -> 19.404147
A24: milkfish (wild-caught) | B24: =H174 -> 0.6 | C24: 0.61 | J24: =(1/(B24*C24*2.20462)) -> 1.2393249 | M24: =1.08*J24 -> 1.3384709
A25: milkfish (farmed) | B25: =H175 -> 0.375 | C25: 0.61 | D25: 0.75 | E25: =(B25*D25*$E$108)*I25 -> 7.482757 | F25: =E25*1.123 -> 8.4031361 | G25: =F25/(B25*C25) -> 36.735021 | H25: =G25*0.453692 -> 16.666385 | I25: 1 | J25: =(1/(B25*C25*2.20462)) -> 1.9829198 | K25: =$G$83 -> 0.4725 | L25: =J25*(K25/(1-K25))*I25 -> 1.7761699 | M25: =(H25+J25+L25)+(0.08*(1-I25)*J25) -> 20.425475
A26: mullets | B26: =H176 -> 0.900367 | C26: 0.5409 | D26: 0.75 | E26: =(B26*D26*$E$108)*I26 -> 2.38947 | F26: =E26*1.123 -> 2.6833748 | G26: =F26/(B26*C26) -> 5.5099136 | H26: =G26*0.453692 -> 2.4998037 | I26: 0.133 | J26: =(1/(B26*C26*2.20462)) -> 0.931386 | K26: 0.22 | L26: =J26*(K26/(1-K26))*I26 -> 0.034938916 | M26: =(H26+J26+L26)+(0.08*(1-I26)*J26) -> 3.5307296 | N26: uses mix of Welfare Footprint’s tilapia & seabream for mortality
A27: pollock | B27: 0.899538 | C27: 0.4962 | J27: =(1/(B27*C27*2.20462)) -> 1.0162253 | M27: =1.08*J27 -> 1.0975233
A28: redfish | B28: =H178 -> 0.46972888 | C28: 0.4726 | D28: 0.75 | E28: =(B28*D28*$E$108)*I28 -> 0.65610852 | F28: =E28*1.123 -> 0.73680987 | G28: =F28/(B28*C28) -> 3.319055 | H28: =G28*0.453692 -> 1.5058287 | I28: 0.07 | J28: =(1/(B28*C28*2.20462)) -> 2.0432677 | K28: 0.175 | L28: =J28*(K28/(1-K28))*I28 -> 0.03033943 | M28: =(H28+J28+L28)+(0.08*(1-I28)*J28) -> 3.731455 | N28: uses Welfare Footprint’s mangrove red snapper mortality
A29: redfish (wild-caught) | B29: =H179 -> 0.429816 | C29: 0.4726 | J29: =(1/(B29*C29*2.20462)) -> 2.2330064 | M29: =1.08*J29 -> 2.4116469
A30: redfish (farmed) | B30: =H180 -> 1 | C30: 0.4726 | D30: 0.75 | E30: =(B30*D30*$E$108)*I30 -> 19.954019 | F30: =E30*1.123 -> 22.408363 | G30: =F30/(B30*C30) -> 47.415072 | H30: =G30*0.453692 -> 21.511839 | I30: 1 | J30: =(1/(B30*C30*2.20462)) -> 0.95978187 | K30: 0.175 | L30: =J30*(K30/(1-K30))*I30 -> 0.20359009 | M30: =(H30+J30+L30)+(0.08*(1-I30)*J30) -> 22.675211
A31: Salmon | B31: =H181 -> 5.4387734 | C31: =((0.76*C33)+(0.24*C32)) -> 0.586992 | D31: 0.96 | E31: =(B31*D31*$E$108)*I31 -> 105.5735 | F31: =E31*1.123 -> 118.55904 | G31: =F31/(B31*C31) -> 37.136546 | H31: =G31*0.453692 -> 16.848554 | I31: 0.76 | J31: =(1/(B31*C31*2.20462)) -> 0.14208005 | K31: =$G$66 -> 0.220625 | L31: =J31*(K31/(1-K31)) -> 0.040219934 | M31: =(H31+J31+L31)+(0.08*(1-I31)*J31) -> 17.033582 | N31: mix 76% farm and 24% wild salmon
A32: salmon (wild-caught) | B32: =H182 -> 3.585556 | C32: 0.5933 | J32: =(1/(B32*C32*2.20462)) -> 0.21322366 | M32: =1.08*J32 -> 0.23028156 | N32: wild
A33: salmon (farmed) | B33: =H183 -> 6.024 | C33: 0.585 | D33: 0.96 | E33: =(B33*D33*$E$108)*I33 -> 153.85985 | F33: =E33*1.123 -> 172.78461 | G33: =F33/(B33*C33) -> 49.030264 | H33: =G33*0.453692 -> 22.244639 | I33: 1 | J33: =(1/(B33*C33*2.20462)) -> 0.12871389 | K33: =$G$66 -> 0.220625 | L33: =J33*(K33/(1-K33)) -> 0.036436251 | M33: =(H33+J33+L33)+(0.08*(1-I33)*J33) -> 22.409789 | N33: farmed
A34: sardines | B34: =H184 -> 0.10053463 | C34: 0.6019 | J34: =(1/(B34*C34*2.20462)) -> 7.4959422 | M34: =1.08*J34 -> 8.0956176
A35: sauries | B35: =H185 -> 0.082741 | C35: 0.5409 | J35: =(1/(B35*C35*2.20462)) -> 10.135111 | M35: =1.08*J35 -> 10.94592
A36: shrimp | B36: =H186 -> 0.02 | C36: 0.57 | D36: 0.86 | E36: =(B36*D36*$E$108)*I36 -> 0.39674974 | F36: =E36*1.123 -> 0.44554996 | G36: =F36/(B36*C36) -> 39.08333 | H36: =G36*0.453692 -> 17.731794 | I36: 0.867 | J36: =(1/(B36*C36*2.20462)) -> 39.788852 | K36: =$G$84 -> 0.234 | L36: =J36*(K36/(1-K36))*I36 -> 10.538228 | M36: =(H36+J36+L36)+(0.08*(1-I36)*J36) -> 68.482227
A37: shrimp (wild-caught) | B37: =H187 -> 0.02 | C37: 0.57 | J37: =(1/(B37*C37*2.20462)) -> 39.788852 | M37: =1.08*J37 -> 42.97196
A38: shrimp (farmed) | B38: =H188 -> 0.02 | C38: 0.57 | D38: 0.86 | E38: =(B38*D38*$E$108)*I38 -> 0.45761216 | F38: =E38*1.123 -> 0.51389846 | G38: =F38/(B38*C38) -> 45.078812 | H38: =G38*0.453692 -> 20.451896 | I38: 1 | J38: =(1/(B38*C38*2.20462)) -> 39.788852 | K38: =$G$84 -> 0.234 | L38: =J38*(K38/(1-K38))*I38 -> 12.154819 | M38: =(H38+J38+L38)+(0.08*(1-I38)*J38) -> 72.395567
A39: smelt | B39: =H189 -> 0.045981 | C39: 0.5933 | J39: =(1/(B39*C39*2.20462)) -> 16.626985 | M39: =1.08*J39 -> 17.957143
A40: sole | B40: =H190 -> 0.33845745 | C40: 0.5275 | J40: =(1/(B40*C40*2.20462)) -> 2.54062 | M40: =1.08*J40 -> 2.7438696
...

Sheet Feed fish
A1: Calculations of feed fish per pig, broiler and laying hen
B4: Estimate | C4: Source
A5: Total annual number of feed fish globally | B5: ='Fish and shellfish calculation'!G108 -> 8.5160833e+11
A6: Portion used for fishmeal | B6: 0.83 | C6: https://g.co/gemini/share/504d9496e46c
A7: Portion used for fish oil | B7: =1-B6 -> 0.17
A8: Number used for fishmeal | B8: =B6*B5 -> 7.0683492e+11
A9: Number used for fish oil | B9: =B7*B5 -> 1.4477342e+11
A10: Total annual number of pigs slaughtered globally | B10: 1511950905 | C10: FAOSTAT 1) Region: World + (Total) 2) Element: Producing Animal Slaughtered 3) Items: Livestock Primary, Meat of pig 4: Year: 2023
A11: Proportion of fish meal used for pigs | B11: 0.07 | C11: https://www.science.org/doi/10.1126/sciadv.adn5650 | D11: https://openknowledge.fao.org/server/api/core/bitstreams/f985caed-cc7a-457e-8107-7ce16c6ef209/content
A12: Feed fish per pig | B12: =(0.07*B8)/B10 -> 32.724901
A14: Fish consumed per broiler and per laying hen (lifetime)
A15: Total fish annually fed as fishmeal to chickens (1%) | B15: =0.01*B8 -> 7.0683492e+09
A16: Broiler lifespan (days) | B16: 49
A17: Laying hen lifespan (days) | B17: 680
A18: Laying hen daily consumption ratio | B18: 0.5
A19: Broilers slaughtered annually | B19: 76245629000 | C19: FAOSTAT 1) Region: World 2) Element: Producing Animal Slaughtered 3) Items: Livestock Primary, Meat of chickens 4: Year: 2023
A20: Global laying hen population | B20: 8300000000 | C20: https://ourworldindata.org/do-better-cages-or-cage-free-environments-really-improve-the-lives-of-hens
A22: Broiler annual demand component | B22: =B19*B16 -> 3736035821000
A23: Laying hen annual demand component | B23: =B20*B18*365 -> 1514750000000
A24: Total demand factor | B24: =B22+B23 -> 5250785821000
A25: Broiler daily fish consumption | B25: =B15/B24 -> 0.0013461507
A26: Laying hen daily fish consumption | B26: =B25*B18 -> 0.00067307537
A27: Broiler lifetime fish consumption | B27: =B25*B16 -> 0.065961386
A28: Laying hen lifetime fish consumption | B28: =B26*B17 -> 0.45769125

Sheet Mortality
A1: Mortality rates
B3: Overall mortality rate | C3: Additional lives per animal | D3: Average age of death (days) | E3: Additional days per animal | F3: Full lifespan | G3: Age of death / full lifespan
A4: Beef | B4: =(1+H68)*B61 -> 0.10257325 | C4: =B4/(1-B4) -> 0.11429707 | D4: =D61 -> 326.28571 | E4: =C4*D4 -> 37.293502 | F4: 1098 | G4: =D4/F4 -> 0.29716367
A5: Broiler chicken | B5: =B18 -> 0.0593 | C5: =B5/(1-B5) -> 0.063038163 | D5: =B19 -> 24.5 | E5: =C5*D5 -> 1.544435 | F5: =7*7 -> 49 | G5: =D5/F5 -> 0.5
A6: Dairy heifers | B6: =D69 -> 0.081784 | C6: =B6/(1-B6) -> 0.089068367 | D6: =E69 -> 126.15813 | E6: =C6*D6 -> 11.236699 | F6: =5.5*365 -> 2007.5 | G6: =D6/F6 -> 0.062843404
A7: Pigs | B7: =B53 -> 0.16519817 | C7: =B7/(1-B7) -> 0.19788909 | D7: =D53 -> 40.984195 | E7: =C7*D7 -> 8.110325 | F7: 168 | G7: =D7/F7 -> 0.24395354
A8: Layer hen | B8: =D29 -> 0.073548387 | C8: =B8/(1-B8)+1 -> 1.0793872 | D8: =E29 -> 83.263158 | E8: =C8*D8 -> 89.873186 | F8: 504 | G8: =D8/F8 -> 0.16520468
A9: Turkey | B9: =B40 -> 0.0825 | C9: =B9/(1-B9) -> 0.089918256 | D9: =C46 -> 52.589196 | E9: =C9*D9 -> 4.7287288 | F9: 137.25 | G9: =D9/F9 -> 0.38316354
A10: Lamb/Mutton | B10: =D88 -> 0.17984 | C10: =B10/(1-B10) -> 0.21927429 | D10: 300 | E10: =C10*D10 -> 65.782286 | F10: 425 | G10: =D10/F10 -> 0.70588235
A11: Goat | B11: =D82 -> 0.272988 | C11: =B11/(1-B11) -> 0.37549311 | D11: 300 | E11: =C11*D11 -> 112.64793 | F11: 275 | G11: =D11/F11 -> 1.0909091
A12: Fish | B12: Calculated in 'Fish and shellfish calculations' sheet
A13: Shellfish | B13: Calculated in 'Fish and shellfish calculations' sheet
A14: Beef includes dairy bull calf mortlity
A16: Calculations/sources
A17: Broiler chickens
A18: Mortality rate | B18: =0.0593 -> 0.0593
A19: Age of death (days) | B19: =49/2 -> 24.5
A20: Sources:
A21: https://www.aphis.usda.gov/animal_health/emergency_management/downloads/documents_manuals/poultry_ind_manual.pdf
A22: https://thepoultrysite.com/articles/mortality-patterns-associated-with-commercial-broiler-production
A24: Layer hens | B24: Mortality rate (pre-slaughter) | C24: Proportion of deaths at each phase | D24: Mortality rate (pre-production) | E24: Age of death (midpoint, days)
A25: Small chicks/brooder (0-8 weeks) | B25: 0.04 | C25: =B25/($B$25+$B$26+$B$27) -> 0.12903226 | D25: =B25 -> 0.04 | E25: =(8*7)/2 -> 28
A26: Grower (8-20 weeks) | B26: 0.15 | C26: =B26/($B$25+$B$26+$B$27) -> 0.48387097 | D26: =B26 -> 0.15 | E26: =((8+20)*7)/2 -> 98
A27: Layer (20-72 weeks) | B27: 0.12 | C27: =B27/($B$25+$B$26+$B$27) -> 0.38709677 | D27: 0 | E27: =(20+72)*7/2 -> 322
A28: Average/total (pre-slaughter) | B28: =(10+14)/2/100 -> 0.12 | E28: =IFERROR(__xludf.dummyfunction("AVERAGE.WEIGHTED(E24:E26,B24:B26)"),175.677419354839) -> 175.67742
A29: Average/total (pre-production) | D29: =(C25+C26)*B28 -> 0.073548387 | E29: =IFERROR(__xludf.dummyfunction("AVERAGE.WEIGHTED(E24:E26,D24:D26)"),83.2631578947369) -> 83.263158
A30: Additrional lives per animal (cell C8) includes one male chick, typically one day old, killed for each female chick
A31: Sources:
A32: http://www.fao.org/3/Y4628E/y4628e03.htm
A33: https://www.aphis.usda.gov/animal_health/nahms/poultry/downloads/layers2013/Layers2013_dr_PartI.pdf
A34: https://www.nrcs.usda.gov/Internet/FSE_DOCUMENTS/nrcseprd380437.pdf
A35: Krautwald-Junghanns M-E, Cramer K, Fischer B, Förster A, Galli R, Kremer F, et al. Current approaches to avoid the culling of day-old male chicks in the layer industry, with specialreference to spectroscopic methods. Poult Sci. 2018;97:749–57.
A37: Turkeys
A38: Hens mortality | B38: 5-6%
A39: Toms mortality | B39: 10-12%
A40: Midpoint | B40: =(5.5+11)/2/100 -> 0.0825
A41: Source: https://www.aphis.usda.gov/animal_health/emergency_management/downloads/documents_manuals/poultry_ind_manual.pdf
B43: Mortality rate | C43: Age of death (midpoint, days)
A44: 0-1 week | B44: 0.02 | C44: =7/2 -> 3.5
A45: 1 week - 4.5 months | B45: =60/980 -> 0.06122449 | C45: =(4.5*30.5)/2 -> 68.625
...

Sheet FAO livestock data U.S.
A1: FAO livestock data
A3: Source: http://www.fao.org/faostat/en/#data/QL
A5: Domain | B5: Area | C5: Element | D5: Item | E5: Year | F5: Unit | G5: Value | H5: Flag Description
A6: Livestock Primary | B6: United States of America | C6: Yield | D6: Eggs, hen, in shell | E6: 2023 | F6: kg/an | G6: 17.077 | H6: Estimated value | I6: *
A7: Livestock Primary | B7: United States of America | C7: Yield (Carcass Weight) | D7: Meat, cattle | E7: 2023 | F7: kg/an | G7: 369 | H7: Official data | I7: *
A8: Livestock Primary | B8: United States of America | C8: Yield (Carcass Weight) | D8: Meat, chicken | E8: 2023 | F8: kg/an | G8: 2.095 | H8: Calculated data | I8: *
A9: Livestock Primary | B9: United States of America | C9: Yield (Carcass Weight) | D9: Meat, pig | E9: 2023 | F9: kg/an | G9: 97 | H9: Calculated data | I9: *
A10: Livestock Primary | B10: United States of America | C10: Yield (Carcass Weight) | D10: Meat, turkey | E10: 2023 | F10: kg/an | G10: 11.46 | H10: Calculated data | I10: *
A11: Livestock Primary | B11: United States of America | C11: Milk Animals | D11: Milk, whole fresh cow | E11: 2023 | F11: Head | G11: 9397500 | H11: Official data | I11: *
A12: Livestock Primary | B12: United States of America | C12: Yield | D12: Milk, whole fresh cow | E12: 2023 | F12: kg/an | G12: =G13/G11*1000 -> 10926.002 | H12: Calculated data | I12: *
A13: Livestock Primary | B13: United States of America | C13: Production | D13: Milk, whole fresh cow | E13: 2023 | F13: tonnes | G13: 102677105 | H13: Official data | I13: *
A14: Livestock Primary | B14: United States of America | C14: Yield | D14: Meat of sheep, fresh or chilled | E14: 2023 | F14: kg/an | G14: 27 | H14: Official data | I14: *
A15: Livestock Primary | B15: United States of America | C15: Yield | D15: Meat of goat | E15: 2023 | F15: kg/an | G15: 15 | H15: Estimated data | I15: *

Sheet Percent retail from FAO yield
A1: Species | B1: FAOSTAT_USDA_Carcass_Yield_Definition | C1: bone-in % of retail sales | D1: Yield at retail relative to FAO carcass yield: bone-in | E1: boneless % of retail sales | F1: Yield at retail relative to FAO carcass yield: boneless | G1: Weighted Average Retail Yield Percent | H1: Loss from original FAO yield | I1: Key_Sources
A2: Beef | B2: Chilled carcass weight (no hide/offal) | C2: 0.1 | D2: 0.75 | E2: 0.9 | F2: 0.65 | G2: =C2*D2+E2*F2 -> 0.66 | H2: =100%-G2 -> 0.34 | I2: https://extension.sdstate.edu/how-much-meat-can-you-expect-fed-steer
A3: Pork | B3: Chilled carcass weight | C3: 0.3 | D3: 0.74 | E3: 0.7 | F3: 0.65 | G3: =C3*D3+E3*F3 -> 0.677 | H3: =100%-G3 -> 0.323 | I3: https://livestock.extension.wisc.edu/articles/how-much-meat-should-a-hog-yield/
A4: Chicken | B4: Ready-to-Cook (RTC) carcass weight | C4: 0.45 | D4: 0.96 | E4: 0.55 | F4: 0.74 | G4: =C4*D4+E4*F4 -> 0.839 | H4: =100%-G4 -> 0.161 | I4: https://www.ams.usda.gov/sites/default/files/media/QAD%20635%20-%20Standard%20Yield.pdf
A5: Turkey | B5: Ready-to-Cook (RTC) carcass weight | C5: 0.6 | D5: 0.96 | E5: 0.4 | F5: 0.74 | G5: =C5*D5+E5*F5 -> 0.872 | H5: =100%-G5 -> 0.128 | I5: https://www.ams.usda.gov/sites/default/files/media/QAD%20635%20-%20Standard%20Yield.pdf
A6: Lamb/Mutton | B6: Chilled carcass weight | C6: 0.6 | D6: 0.7 | E6: 0.4 | F6: 0.465 | G6: =C6*D6+E6*F6 -> 0.606 | H6: =100%-G6 -> 0.394 | I6: https://livestock.extension.wisc.edu/articles/how-much-meat-should-a-lamb-yield/
A7: Goat | B7: Chilled carcass weight | C7: 0.6 | D7: 0.7 | E7: 0.4 | F7: 0.465 | G7: =C7*D7+E7*F7 -> 0.606 | H7: =100%-G7 -> 0.394 | I7: https://livestock.extension.wisc.edu/articles/how-much-meat-should-a-lamb-yield/
A8: Eggs | B8: Kg per 1000 eggs | G8: 0.985 | H8: 0.015 | I8: https://ers.usda.gov/sites/default/files/_laserfiche/DataFiles/50472/meat.xls?v=74023
A9: Dairy | B9: % Food | G9: =E39 -> 0.94929354 | I9: https://www.fao.org/faostat/en/#data/FBS
A13: FAO FOOD BALANCES: COW MILK
A14: 1) milk excluding butter | B14: Production | C14: 102747 | D14: 1000 t
B15: Import quantity | C15: 6627 | D15: 1000 t
B16: Export quantity | C16: 4495 | D16: 1000 t
B17: Stock Variation | C17: 120 | D17: 1000 t
B18: Domestic supply quantity | C18: 104759 | D18: 1000 t | E18: =C14+C15-C16-C17 -> 104759
A20: Not for human food | B20: Other uses (non-food) | C20: 4802 | D20: 1000 t
A21: Not for human food | B21: Feed | C21: 638 | D21: 1000 t
A22: Not for human food | B22: Residuals | C22: -96 | D22: 1000 t | E22: =C20+C21+C22 -> 5344
A24: For food | B24: Food | C24: 77915 | D24: 1000 t
A25: For food | B25: Processing | C25: 21500 | D25: 1000 t | E25: =C25+C24 -> 99415
A27: 2) butter/ghee | B27: Production | C27: 945 | D27: 1000 t
B28: Import quantity | C28: 53 | D28: 1000 t
B29: Export quantity | C29: 82 | D29: 1000 t
B30: Stock Variation | C30: 8 | D30: 1000 t
B31: Domestic supply quantity | C31: 908 | D31: 1000 t | E31: =C27+C28-C29-C30 -> 908
A33: For food | B33: Food | C33: 894 | D33: 1000 t | E33: =C33 -> 894
A35: Not for human food | B35: Losses | C35: 14 | D35: 1000 t | E35: 14
C37: Total supply: milk+butter | E37: =E18+E31 -> 105667
C38: Total for food | E38: =E25+E33 -> 100309
C39: % for food | E39: =E38/E37 -> 0.94929354

Sheet Fishcount fish weights
A1: Fishcount fish weights
A3: Source: http://fishcount.org.uk/studydatascreens2/2017/numbers-of-farmed-fish-A0-2017.php?sort2/full; http://fishcount.org.uk/studydatascreens/2016/numbers-of-wild-fish-A0-2016.php
A5: Species | B5: Estimated mean weight (grams) | C5: Generic mean weight (grams) | D5: Mean weight (grams, estimated and generic combined) | E5: Minimum weight (grams) | F5: Maximum weight (grams) | G5: Farmed or wild caught
A6: Grass carp(=White amur) (Ctenopharyngodon idellus) | B6: 500-2,500 | D6: 500-2,500 | E6: 500 | F6: 2500 | G6: Farmed
A7: Silver carp (Hypophthalmichthys molitrix) | B7: 300-1,500 | D7: 300-1,500 | E7: 300 | F7: 1500 | G7: Farmed
A8: Nile tilapia (Oreochromis niloticus) | B8: 250-800 | D8: 250-800 | E8: 250 | F8: 800 | G8: Farmed
A9: Common carp (Cyprinus carpio) | B9: 500-2,500 | D9: 500-2,500 | E9: 500 | F9: 2500 | G9: Farmed
A10: Bighead carp (Hypophthalmichthys nobilis) | B10: 500-1,500 | D10: 500-1,500 | E10: 500 | F10: 1500 | G10: Farmed
A11: Carassius spp (Carassius spp) | B11: 150-400 | D11: 150-400 | E11: 150 | F11: 400 | G11: Farmed
A12: Catla (Catla catla) | B12: 300-2,000 | D12: 300-2,000 | E12: 300 | F12: 2000 | G12: Farmed
A13: Atlantic salmon (Salmo salar) | B13: 3,614-8,434 | D13: 3,614-8,434 | E13: 3614 | F13: 8434 | G13: Farmed
A14: Roho labeo (Labeo rohita) | B14: 300-1,500 | D14: 300-1,500 | E14: 300 | F14: 1500 | G14: Farmed
A15: Pangas catfishes nei (Pangasius spp) | B15: 500-1,500 | D15: 500-1,500 | E15: 500 | F15: 1500 | G15: Farmed
A16: Milkfish (Chanos chanos) | B16: 250-500 | D16: 250-500 | E16: 250 | F16: 500 | G16: Farmed
A17: Tilapias nei (Oreochromis(=Tilapia) spp) | B17: 250-800 | D17: 250-800 | E17: 250 | F17: 800 | G17: Farmed
... A53: American yellow perch (Perca flavescens) | B53: 227-227 | D53: 227-227 | E53: 227 | F53: 227 | G53: Farmed
A54: Marine fishes nei | C54: 38-97 | D54: 38-97 | E54: 38 | F54: 97 | G54: Wild caught
A55: Freshwater fishes nei | C55: 38-97 | D55: 38-97 | E55: 38 | F55: 97 | G55: Wild caught
A56: Anchoveta(=Peruvian anchovy) (Engraulis ringens) | B56: 10-29 | D56: 10-29 | E56: 10 | F56: 29 | G56: Wild caught
A57: Alaska pollock(=Walleye poll.) (Theragra chalcogramma) | B57: 227-1,000 | D57: 227-1,000 | E57: 227 | F57: 1000 | G57: Wild caught
A58: Skipjack tuna (Katsuwonus pelamis) | B58: 2,000-10,000 | D58: 2,000-10,000 | E58: 2000 | F58: 10000 | G58: Wild caught
A59: Atlantic herring (Clupea harengus) | B59: 100-600 | D59: 100-600 | E59: 100 | F59: 600 | G59: Wild caught
A60: Pacific chub mackerel (Scomber japonicus) | B60: 100-750 | D60: 100-750 | E60: 100 | F60: 750 | G60: Wild caught
A61: Largehead hairtail (Trichiurus lepturus) | B61: 32-713 | D61: 32-713 | E61: 32 | F61: 713 | G61: Wild caught
A62: Japanese anchovy (Engraulis japonicus) | B62: 20-22 | D62: 20-22 | E62: 20 | F62: 22 | G62: Wild caught
A63: Yellowfin tuna (Thunnus albacares) | B63: 5,000-20,000 | D63: 5,000-20,000 | E63: 5000 | F63: 20000 | G63: Wild caught
A64: Scads nei (Decapterus spp) | B64: 63-231 | D64: 63-231 | E64: 63 | F64: 231 | G64: Wild caught
A65: European pilchard(=Sardine) (Sardina pilchardus) | B65: 69-127 | D65: 69-127 | E65: 69 | F65: 127 | G65: Wild caught
A66: Atlantic cod (Gadus morhua) | B66: 800-4,000 | D66: 800-4,000 | E66: 800 | F66: 4000 | G66: Wild caught
A67: Sardinellas nei (Sardinella spp) | B67: 7-224 | D67: 7-224 | E67: 7 | F67: 224 | G67: Wild caught
... A70: Chilean jack mackerel (Trachurus murphyi) | B70: 200-1,000 | D70: 200-1,000 | E70: 200 | F70: 1000 | G70: Wild caught
A71: Croakers, drums nei | C71: 38-96 | D71: 38-96 | E71: 38 | F71: 96 | G71: Wild caught
A72: Cyprinids nei | C72: 38-96 | D72: 38-96 | E72: 38 | F72: 96 | G72: Wild caught
A73: Araucanian herring (Strangomera bentincki) | B73: 27-34 | D73: 27-34 | E73: 27 | F73: 34 | G73: Wild caught
A74: Threadfin breams nei | C74: 38-96 | D74: 38-96 | E74: 38 | F74: 96 | G74: Wild caught
A75: European sprat (Sprattus sprattus) | B75: 17-17 | D75: 17-17 | E75: 17 | F75: 17 | G75: Wild caught
A76: Capelin (Mallotus villosus) | B76: 17-50 | D76: 17-50 | E76: 17 | F76: 50 | G76: Wild caught
A77: Seerfishes nei | C77: 38-96 | D77: 38-96 | E77: 38 | F77: 96 | G77: Wild caught
A78: Indian oil sardine (Sardinella longiceps) | B78: 87-132 | D78: 87-132 | E78: 87 | F78: 132 | G78: Wild caught
A79: Gulf menhaden (Brevoortia patronus) | B79: 234-234 | D79: 234-234 | E79: 234 | F79: 234 | G79: Wild caught
...

Sheet Elasticity adjustments
D2: Elasticity factor | E2: Elasticity adjusted lives direct | F2: Elasticity adjusted lives total
A3: Animal fats | B3: ='Overall Estimates'!C18 -> 0.10617053 | C3: ='Overall Estimates'!D18 -> 0.67132313 | D3: =(0.37*D6)+(0.32*D4)+(0.2*D8)+(0.06*D5)+(0.05*D56) -> 0.72195 | E3: =B3*D3 -> 0.076649817 | F3: =C3*E3 -> 0.051456795
A4: Beef | B4: ='Overall Estimates'!C19 -> 0.001724731 | C4: ='Overall Estimates'!D19 -> 0.0019218627 | D4: 0.68 | E4: =B4*D4 -> 0.0011728171 | F4: =C4*E4 -> 2.2539934e-06
A5: LAMB/MUTTON | B5: ='Overall Estimates'!C23 -> 0.036128467 | C5: ='Overall Estimates'!D23 -> 0.044050511 | D5: 0.73 | E5: =B5*D5 -> 0.026373781 | F5: =C5*E5 -> 0.0011617786
A6: Pork | B6: ='Overall Estimates'!C25 -> 0.053487207 | C6: ='Overall Estimates'!D25 -> 0.058296683 | D6: 0.74 | E6: =B6*D6 -> 0.039580533 | F6: =C6*E6 -> 0.0023074138
A7: GOAT | B7: ='Overall Estimates'!C26 -> 0.14293917 | C7: ='Overall Estimates'!D26 -> 0.22232666 | D7: 0.73 | E7: =B7*D7 -> 0.10434559 | F7: =C7*E7 -> 0.023198807
A8: Chicken | B8: ='Overall Estimates'!C26 -> 0.14293917 | C8: ='Overall Estimates'!D26 -> 0.22232666 | D8: 0.76 | E8: =B8*D8 -> 0.10863377 | F8: =C8*E8 -> 0.024152183
A9: Turkey | B9: ='Overall Estimates'!C28 -> 8.0689406e-05 | C9: ='Overall Estimates'!D28 -> 8.7876279e-05 | D9: 0.75 | E9: =B9*D9 -> 6.0517054e-05 | F9: =C9*E9 -> 5.3180135e-09
A10: Dairy milk | B10: ='Overall Estimates'!C27 -> 1.2828204e-05 | C10: ='Overall Estimates'!D27 -> 1.3970792e-05 | D10: 0.56 | E10: =B10*D10 -> 7.1837944e-06 | F10: =C10*E10 -> 1.003633e-10
A11: Ice cream | B11: ='Overall Estimates'!C34 -> 2.1038255e-05 | C11: ='Overall Estimates'!D34 -> 2.2912098e-05 | D11: 0.56 | E11: =B11*D11 -> 1.1781423e-05 | F11: =C11*E11 -> 2.6993712e-10
A12: Cheese | B12: ='Overall Estimates'!C35 -> 9.1593379e-05 | C12: ='Overall Estimates'!D35 -> 9.9751452e-05 | D12: 0.56 | E12: =B12*D12 -> 5.1292292e-05 | F12: =C12*E12 -> 5.1164806e-09
A13: Yogurt | B13: ='Overall Estimates'!C40 -> 1.457284e-05 | C13: ='Overall Estimates'!D40 -> 1.5870819e-05 | D13: 0.56 | E13: =B13*D13 -> 8.1607905e-06 | F13: =C13*E13 -> 1.2951843e-10
A14: Butter | B14: ='Overall Estimates'!C40 -> 1.457284e-05 | C14: ='Overall Estimates'!D40 -> 1.5870819e-05 | D14: 0.56 | E14: =B14*D14 -> 8.1607905e-06 | F14: =C14*E14 -> 1.2951843e-10
A15: Buttermilk | B15: ='Overall Estimates'!C40 -> 1.457284e-05 | C15: ='Overall Estimates'!D40 -> 1.5870819e-05 | D15: 0.56 | E15: =B15*D15 -> 8.1607905e-06 | F15: =C15*E15 -> 1.2951843e-10
A16: Concentrated milk | B16: ='Overall Estimates'!C40 -> 1.457284e-05 | C16: ='Overall Estimates'!D40 -> 1.5870819e-05 | D16: 0.56 | E16: =B16*D16 -> 8.1607905e-06 | F16: =C16*E16 -> 1.2951843e-10
A17: Cream | B17: ='Overall Estimates'!C40 -> 1.457284e-05 | C17: ='Overall Estimates'!D40 -> 1.5870819e-05 | D17: 0.56 | E17: =B17*D17 -> 8.1607905e-06 | F17: =C17*E17 -> 1.2951843e-10
A18: Ghee | B18: ='Overall Estimates'!C40 -> 1.457284e-05 | C18: ='Overall Estimates'!D40 -> 1.5870819e-05 | D18: 0.56 | E18: =B18*D18 -> 8.1607905e-06 | F18: =C18*E18 -> 1.2951843e-10
A19: Lactose powder | B19: ='Overall Estimates'!C40 -> 1.457284e-05 | C19: ='Overall Estimates'!D40 -> 1.5870819e-05 | D19: 0.56 | E19: =B19*D19 -> 8.1607905e-06 | F19: =C19*E19 -> 1.2951843e-10
A20: Low fat yogurt | B20: =#REF! -> #REF! | C20: =#REF! -> #REF! | D20: 0.56 | E20: =B20*D20 -> #REF! | F20: =C20*E20 -> #REF!
A21: Milk powder | B21: =#REF! -> #REF! | C21: =#REF! -> #REF! | D21: 0.56 | E21: =B21*D21 -> #REF! | F21: =C21*E21 -> #REF!
A22: Skim milk | B22: =#REF! -> #REF! | C22: =#REF! -> #REF! | D22: 0.56 | E22: =B22*D22 -> #REF! | F22: =C22*E22 -> #REF!
A23: Whey powder | B23: =#REF! -> #REF! | C23: =#REF! -> #REF! | D23: 0.56 | E23: =B23*D23 -> #REF! | F23: =C23*E23 -> #REF!
A24: Eggs | B24: =#REF! -> #REF! | C24: =#REF! -> #REF! | D24: 0.91 | E24: =B24*D24 -> #REF! | F24: =C24*E24 -> #REF!
A25: Fish (unidentified) | B25: ='Overall Estimates'!C41 -> 36.618162 | C25: ='Overall Estimates'!D41 -> 39.547615 | D25: 0.695 | E25: =B25*D25 -> 25.449623 | F25: =C25*E25 -> 1006.4719
A26: Catfish | B26: ='Overall Estimates'!C42 -> 0.18122315 | C26: ='Overall Estimates'!D42 -> 2.0493389 | D26: 0.695 | E26: =B26*D26 -> 0.12595009 | F26: =C26*E26 -> 0.25811443
A27: Milkfish | B27: ='Overall Estimates'!C43 -> 0.15386051 | C27: ='Overall Estimates'!D43 -> 0.16616935 | D27: 0.695 | E27: =B27*D27 -> 0.10693305 | F27: =C27*E27 -> 0.017768996
A28: Miscellaneouos Carp | B28: ='Overall Estimates'!C44 -> 1.6356312 | C28: ='Overall Estimates'!D44 -> 13.897033 | D28: 0.695 | E28: =B28*D28 -> 1.1367637 | F28: =C28*E28 -> 15.797643
A29: Shrimp | B29: =#REF! -> #REF! | C29: =#REF! -> #REF! | D29: 0.695 | E29: =B29*D29 -> #REF! | F29: =C29*E29 -> #REF!
A30: Silver or Bighead Carp | B30: =#REF! -> #REF! | C30: =#REF! -> #REF! | D30: 0.695 | E30: =B30*D30 -> #REF! | F30: =C30*E30 -> #REF!
A31: Tilapia | B31: ='Overall Estimates'!C45 -> 0.066660334 | C31: ='Overall Estimates'!D45 -> 0.066660334 | D31: 0.695 | E31: =B31*D31 -> 0.046328932 | F31: =C31*E31 -> 0.0030883021
A32: Trout | B32: ='Overall Estimates'!C46 -> 0.31791216 | C32: ='Overall Estimates'!D46 -> 0.31791216 | D32: 0.695 | E32: =B32*D32 -> 0.22094895 | F32: =C32*E32 -> 0.07024236
A33: Anchovies | B33: ='Overall Estimates'!C47 -> 0.32360522 | C33: ='Overall Estimates'!D47 -> 6.7670129 | D33: 0.695 | E33: =B33*D33 -> 0.22490563 | F33: =C33*E33 -> 1.5219393
A34: Bass | B34: ='Overall Estimates'!C48 -> 0.033707086 | C34: ='Overall Estimates'!D48 -> 0.036403653 | D34: 0.695 | E34: =B34*D34 -> 0.023426425 | F34: =C34*E34 -> 0.00085280744
A35: Billfishes | B35: ='Overall Estimates'!C49 -> 1.0132165 | C35: ='Overall Estimates'!D49 -> 8.6125191 | D35: 0.695 | E35: =B35*D35 -> 0.70418543 | F35: =C35*E35 -> 6.0648105
A36: Bluefin tuna | B36: ='Overall Estimates'!C50 -> 0.33907019 | C36: ='Overall Estimates'!D50 -> 0.3661958 | D36: 0.695 | E36: =B36*D36 -> 0.23565378 | F36: =C36*E36 -> 0.086295426
A37: Bonitos | B37: ='Overall Estimates'!C51 -> 0.090585257 | C37: ='Overall Estimates'!D51 -> 0.097832077 | D37: 0.695 | E37: =B37*D37 -> 0.062956753 | F37: =C37*E37 -> 0.00615919
A38: Cod | B38: ='Overall Estimates'!C52 -> 0.96401553 | C38: ='Overall Estimates'!D52 -> 1.9280311 | D38: 0.695 | E38: =B38*D38 -> 0.66999079 | F38: =C38*E38 -> 1.2917631
A39: Congers | B39: ='Overall Estimates'!C53 -> 0.84544549 | C39: ='Overall Estimates'!D53 -> 10.019761 | D39: 0.695 | E39: =B39*D39 -> 0.58758461 | F39: =C39*E39 -> 5.8874576
A40: Flounder | B40: ='Overall Estimates'!C54 -> 1.8563316 | C40: ='Overall Estimates'!D54 -> 2.0048381 | D40: 0.695 | E40: =B40*D40 -> 1.2901504 | F40: =C40*E40 -> 2.5865428
A41: Haddock | B41: ='Overall Estimates'!C55 -> 0.67713573 | C41: ='Overall Estimates'!D55 -> 0.73130659 | D41: 0.695 | E41: =B41*D41 -> 0.47060933 | F41: =C41*E41 -> 0.3441597
...

Sheet Days of their lives
A1: PRELIMINARY: EARLY IN PROGRESS
B2: Yield | C2: Years producing product (eggs and dairy) | D2: Lifetime in days | E2: Lifetime in days including indirect effects (feed fish, mortality, male chicks and male calves) | F2: Loss adjusted proportion | G2: 1/milk solids proportion | H2: Total retail weight per day of life (kg) | I2: Total retail weight per day of life including indirect effects (kg)
A3: Beef | B3: ='FAO livestock data U.S.'!G7 -> 369 | C3: 1 | D3: 1098 | E3: =D3+Mortality!E4 -> 1135.2935 | F3: ='Percent retail from FAO yield'!G2 -> 0.66 | H3: =B3*C3*F3/D3 -> 0.22180328 | I3: =B3*C3*F3/E3 -> 0.21451721
A4: Chicken | B4: ='FAO livestock data U.S.'!G8 -> 2.095 | C4: 1.6 | D4: 49 | E4: =D4+Mortality!E5 -> 50.544435 | F4: ='Percent retail from FAO yield'!G4 -> 0.839 | H4: =B4*C4*F4/D4 -> 0.057394449 | I4: =B4*C4*F4/E4 -> 0.055640705
A5: Dairy | B5: ='FAO livestock data U.S.'!G12 -> 10926.002 | C5: 3 | D5: =5.5*365 -> 2007.5 | E5: =D5+Mortality!E6 -> 2018.7367 | F5: ='Percent retail from FAO yield'!G9 -> 0.94929354 | H5: =(B5*C5*F5)/D5 -> 15.49985 | I5: =B5*C5*F5/E5 -> 15.413575
A6: Dairy ice cream | B6: ='FAO livestock data U.S.'!G12 -> 10926.002 | C6: 3 | D6: =5.5*365 -> 2007.5 | E6: =D6+Mortality!E6 -> 2018.7367 | F6: ='Percent retail from FAO yield'!G9 -> 0.94929354 | G6: =1/('Milk solids proportion'!B11) -> 0.6097561 | H6: =(B6*C6*F6*G6)/D6 -> 9.4511283 | I6: =B6*C6*F6*G6/E6 -> 9.3985214
A7: Dairy cheese | B7: ='FAO livestock data U.S.'!G12 -> 10926.002 | C7: 3 | D7: =5.5*365 -> 2007.5 | E7: =D7+Mortality!E6 -> 2018.7367 | F7: ='Percent retail from FAO yield'!G9 -> 0.94929354 | G7: =1/('Milk solids proportion'!B7) -> 0.21881838 | H7: =B7*C7*F7*G7/D7 -> 3.3916522 | I7: =B7*C7*F7*G7/E7 -> 3.3727735
A8: Dairy yoghurt | B8: ='FAO livestock data U.S.'!G12 -> 10926.002 | C8: 3 | D8: =5.5*365 -> 2007.5 | E8: =D8+Mortality!E6 -> 2018.7367 | F8: ='Percent retail from FAO yield'!G9 -> 0.94929354 | G8: =1/('Milk solids proportion'!B17) -> 0.88028169 | H8: =B8*C8*F8*G8/D8 -> 13.644234 | I8: =B8*C8*F8*G8/E8 -> 13.568288
A9: Dairy butter | B9: ='FAO livestock data U.S.'!G12 -> 10926.002 | C9: 3 | D9: =5.5*365 -> 2007.5 | E9: =D9+Mortality!E6 -> 2018.7367 | F9: ='Percent retail from FAO yield'!G9 -> 0.94929354 | G9: =1/('Milk solids proportion'!B5) -> 0.15898251 | H9: =B9*C9*F9*G9/D9 -> 2.4642051 | I9: =B9*C9*F9*G9/E9 -> 2.4504889
A10: Pork | B10: ='FAO livestock data U.S.'!G9 -> 97 | C10: 1 | D10: 168 | E10: =D10+Mortality!E7 -> 176.11033 | F10: ='Percent retail from FAO yield'!G3 -> 0.677 | H10: =B10*C10*F10/D10 -> 0.3908869 | I10: =B10*C10*F10/E10 -> 0.37288558
A11: Eggs | B11: ='FAO livestock data U.S.'!G6 -> 17.077 | C11: 1 | D11: 680 | E11: =D11+Mortality!E8+1 -> 770.87319 | F11: ='Percent retail from FAO yield'!G8 -> 0.985 | H11: =B11*C11*F11/D11 -> 0.024736537 | I11: =B11*C11*F11/E11 -> 0.021820509
A12: Turkey | B12: ='FAO livestock data U.S.'!G10 -> 11.46 | C12: 1 | D12: 137 | E12: =D12+Mortality!E9 -> 141.72873 | F12: ='Percent retail from FAO yield'!G7 -> 0.606 | H12: =B12*C12*F12/D12 -> 0.050691679 | I12: =B12*C12*F12/E12 -> 0.049000369
A13: Fish | B13: ='Fish and shellfish calculation'!B42 -> 0.60584385 | D13: 326.1215 | E13: 358.3 | F13: ='Fish and shellfish calculation'!C42 -> 0.37 | H13: =B13*F13/D13 -> 0.00068735801 | I13: =B13*F13/E13 -> 0.0006256272
A14: Shrimp | B14: =#REF! -> #REF! | D14: 149.84 | E14: 162.7 | F14: =#REF! -> #REF! | H14: =B14*F14/D14 -> #REF! | I14: =B14*F14/E14 -> #REF!
A15: Crab | B15: ='Fish and shellfish calculation'!B41 -> 2 | D15: 1 | E15: 1 | F15: ='Fish and shellfish calculation'!C41 -> 0.5409 | H15: =B15*F15/D15 -> 1.0818 | I15: =B15*F15/E15 -> 1.0818
